Workbook

Sheet 票房分析总览
A1: 电影票房分析总览表
A2: 数据范围：映前想看 · 预售票房 · 累计票房 | 制作日期：2026-08-06
A3: 电影名称 | B3: 上映日期 | C3: 状态 | D3: 类型 | E3: 主演 | F3: 映前想看合计 | G3: 日均想看 | H3: 想看峰值 | I3: 预售总票房 | J3: 累计总票房
A4: 抓娃娃 | B4: 2024-07-16 | C4: 已上映 | D4: 喜剧/家庭 | E4: 沈腾、马丽 | F4: =想看数据明细!B13 | G4: =想看数据明细!B14 | H4: =想看数据明细!B15 | I4: =预售数据明细!C14 * 10000 | J4: 3300000000
A5: 独行月球 | B5: 2022-07-29 | C5: 已上映 | D5: 科幻/喜剧 | E5: 沈腾、马丽 | F5: =想看数据明细!C16 | G5: =想看数据明细!C17 | H5: =想看数据明细!C18 | I5: =预售数据明细!E14 * 10000 | J5: 3103000000
A6: 欢迎来龙餐馆 | B6: 2026-08-11 | C6: 待上映 | D6: 战争/剧情 | E6: 沈腾、李治廷 | F6: =想看数据明细!D19 | G6: =想看数据明细!D20 | H6: =想看数据明细!D21 | I6: 4718000 | J6: 待上映
A8: 数据来源：猫眼专业版；想看数据由用户提供。预售/票房金额为关键节点公开数据。

Sheet 票房预估分析
A1: 《欢迎来龙餐馆》票房与预售预估分析
A2: 预估日期：2026-08-06 | 影片8月11日上映，8月8-10日超前点映
A3: 一、参照影片票房数据对比
A4: 参照维度 | B4: 我不是药神 | C4: 奇迹·笨小孩 | D4: 抓娃娃 | E4: 独行月球 | F4: 飞驰人生3
A5: 上映年份 | B5: 2018 | C5: 2022 | D5: 2024 | E5: 2022 | F5: 2026
A6: 导演 | B6: 文牧野 | C6: 文牧野 | D6: 闫非/彭大魔 | E6: 张吃鱼 | F6: 韩寒
A7: 主演 | B7: 徐峥 | C7: 易烊千玺 | D7: 沈腾/马丽 | E7: 沈腾/马丽 | F7: 沈腾
A8: 类型 | B8: 现实/剧情 | C8: 现实/剧情 | D8: 喜剧/家庭 | E8: 科幻/喜剧 | F8: 喜剧/运动
A9: 首日票房(亿) | B9: 1.6 | C9: 1.82 | D9: 6.5 | E9: 2 | F9: 春节档
A10: 首周票房(亿) | B10: — | C10: 6.68 | D10: 11 | E10: 10 | F10: 29.27
A11: 累计总票房(亿) | B11: 31 | C11: 13.79 | D11: 33 | E11: 31.03 | F11: 38
A12: 豆瓣评分 | B12: 9 | C12: 7.4 | D12: 7.3 | E12: 6.9 | F12: —
A14: 二、票房预估模型（三档情景）
A15: 预估指标 | B15: 保守预估 | C15: 中性预估（基准） | D15: 乐观预估 | E15: 预估依据
A16: 预售票房(含点映) | B16: 5000万-8000万 | C16: 8000万-1.2亿 | D16: 1.2亿-1.8亿 | E16: 极限定档仅6天预售期；参照抓娃娃映前10天预售1713.8万、独行月球5034.9万；沈腾+文牧野组合有溢价
A17: 首日票房(含点映) | B17: 1.5亿-2.5亿 | C17: 2.5亿-3.5亿 | D17: 3.5亿-5亿 | E17: 3天点映蓄势+周二上映；参照药神1.6亿、奇迹1.82亿、独行月球2亿；沈腾单片首日有溢价
A18: 首周票房 | B18: 6亿-9亿 | C18: 9亿-13亿 | D18: 13亿-18亿 | E18: 参照抓娃娃4天11亿、独行月球3天10亿、奇迹首周6.68亿
A19: 累计总票房 | B19: 22亿-28亿 | C19: 30亿-35亿 | D19: 38亿-45亿 | E19: 业内分歧大：看空25亿以下、保守30-35亿、乐观40-50亿
A21: 三、核心预估结论
A22: 指标 | B22: 预估中值 | C22: 区间 | D22: 置信度 | E22: 关键驱动因素 | F22: 主要风险
A23: 预售票房 | B23: 1亿 | C23: 0.5-1.8亿 | D23: 中 | E23: 沈腾号召力+文牧野口碑+3天点映 | F23: 极限定档预售期短
A24: 首日票房 | B24: 3亿 | C24: 1.5-5亿 | D24: 中 | E24: 点映口碑发酵+排片保障 | F24: 周二非传统上映日
A25: 累计总票房 | B25: 32亿 | C25: 22-45亿 | D25: 中低 | E25: 主创组合+暑期压轴+长尾窗口 | F25: 战争题材受众受限+暑期档偏弱
A26: 四、预估逻辑与权重分析
A27: 利好因素 | B27: 权重
A28: 沈腾票房号召力 | B28: ★★★★★ | C28: 主演累计票房破400亿，近作均30亿+；《飞驰人生3》38亿春节档冠军
A29: 文牧野导演品牌 | B29: ★★★★☆ | C29: 《药神》31亿+豆瓣9.0；《奇迹》13.79亿；现实主义爆款保证
A30: 暑期档压轴定位 | B30: ★★★★☆ | C30: 8月11日上映吃满暑期尾+中秋国庆预热长尾；竞品蜘蛛侠窗口仅2-3周
A31: 3天超前点映 | B31: ★★★☆☆ | C31: 8月8-10日全国点映，口碑提前发酵，参照抓娃娃点映策略
A32: 塔斯汀万店联名 | B32: ★★★☆☆ | C32: 万店规模联名营销，产业链提前锁定上映窗口
A34: 风险因素 | B34: 权重
A35: 极限定档宣发短 | B35: ★★★★☆ | C35: 8月5日官宣8月11日上映，仅6天；想看积累不足（映前6天仅24881）
A36: 战争/剧情题材 | B36: ★★★★☆ | C36: 非纯喜剧，受众面窄于抓娃娃/独行月球；中东战争背景有观影门槛
A37: 暑期档整体偏弱 | B37: ★★★☆☆ | C37: 截至8月3日75亿，无30亿+影片；去年暑期冠军仅28.9亿
A38: 周二非传统上映 | B38: ★★☆☆☆ | C38: 工作日上映首日爆发力受限，依赖点映+周末走势
A39: 蜘蛛侠竞争 | B39: ★★☆☆☆ | C39: 蜘蛛侠内地预测16亿，窗口重叠2-3周；但类型受众差异大
A41: 注：以上预估基于截至2026-08-06的公开信息，采用参照影片对比+情景分析法。实际票房将受点映口碑、排片竞争、市场环境等动态因素影响，存在较大不确定性。
A42: 数据来源：猫眼专业版。

Sheet 预售数据明细
A1: 映前预售数据逐日明细（当日新增）
A2: 数据来源：猫眼专业版 | 抓娃娃上映2024-07-16 · 独行月球上映2022-07-29
A3: 映前天数 | B3: 抓娃娃日期 | C3: 抓娃娃当日新增(万) | D3: 独行月球日期 | E3: 独行月球当日新增(万)
A4: 映前1天 | B4: 2024-07-15 | C4: 1382.6 | D4: 2022-07-28 | E4: 2735
A5: 映前2天 | B5: 2024-07-14 | C5: 156.4 | D5: 2022-07-27 | E5: 896
A6: 映前3天 | B6: 2024-07-13 | C6: 34.5 | D6: 2022-07-26 | E6: 400.4
A7: 映前4天 | B7: 2024-07-12 | C7: 17.2 | D7: 2022-07-25 | E7: 272
A8: 映前5天 | B8: 2024-07-11 | C8: 9.5 | D8: 2022-07-24 | E8: 203.4
A9: 映前6天 | B9: 2024-07-10 | C9: 11.3 | D9: 2022-07-23 | E9: 181.6
A10: 映前7天 | B10: 2024-07-09 | C10: 9.8 | D10: 2022-07-22 | E10: 258.2
A11: 映前8天 | B11: 2024-07-08 | C11: 3.3 | D11: 2022-07-21 | E11: 43.6
A12: 映前9天 | B12: 2024-07-07 | C12: 13.4 | D12: 2022-07-20 | E12: 35.8
A13: 映前10天 | B13: 2024-07-06 | C13: 63 | D13: 2022-07-19 | E13: 8.9
A14: 映前1-10天合计 | C14: =SUM(C4:C13) | E14: =SUM(E4:E13)
A15: 注：以上为映前1-10天的当日新增预售数据。映前1天预售集中爆发，抓娃娃新增1382.6万、独行月球新增2735.0万。合计为10天区间总计，实际累计预售可能含更早天数。

Sheet 来龙餐馆预售追踪
A1: 《欢迎来龙餐馆》点映及预售票房追踪
A2: 上映日期：2026-08-11 | 数据来源：猫眼专业版
A3: 获取时间 | B3: 映前天数 | C3: 点映及预售总票房(万) | D3: 预售总票房(万) | E3: 首日预售票房(万) | F3: 首日排片占比 | G3: 首日黄金场占比 | H3: 备注
A4: 2026-08-06 14:45 | B4: 映前5天 | C4: 180.3 | D4: 3.5 | E4: 3 | F4: 77.1% | G4: 78.6% | H4: 预售刚开启；首日预售排名No.1；竞争趋势领先蜘蛛侠(1.8万)
A5: 2026-08-06 14:55 | B5: 映前5天 | C5: 191.8 | H5: 数据来源：猫眼专业版 | 点映及预售总票房191.8万
A6: 2026-08-06 15:01 | B6: 映前5天 | C6: 200.2 | H6: 数据来源：猫眼专业版 | 点映及预售总票房200.2万
A7: 2026-08-06 15:03 | B7: 映前5天 | C7: 203.7 | H7: 数据来源：猫眼专业版 | 点映及预售总票房203.7万
A8: 2026-08-06 16:53 | B8: 映前5天 | C8: 307.6 | H8: 数据来源：猫眼专业版 | 点映及预售总票房307.6万
A9: 2026-08-06 17:37 | B9: 映前5天 | C9: 334.2 | H9: 数据来源：猫眼专业版 | 点映及预售总票房334.2万
A10: 2026-08-06 18:03 | B10: 映前5天 | C10: 353.1 | H10: 数据来源：猫眼专业版 | 点映及预售总票房353.1万
A11: 2026-08-06 19:06 | B11: 映前5天 | C11: 396.2 | H11: 数据来源：猫眼专业版 | 点映及预售总票房396.2万
A12: 2026-08-06 20:02 | B12: 映前5天 | C12: 434.2 | H12: 数据来源：猫眼专业版 | 点映及预售总票房434.2万
A13: 2026-08-06 21:04 | B13: 映前5天 | C13: 471.8 | H13: 数据来源：猫眼专业版 | 点映及预售总票房471.8万
A27: 注：本表逐条记录猫眼专业版截图数据。8月8-10日为超前点映日，点映票房将纳入'点映及预售总票房'。请定期截图更新。
A28: 2026-08-06 22:50 | B28: 映前5天 | C28: 定时任务 | D28: 555.3 | E28: 猫眼专业版
A29: 2026-08-06 23:00 | B29: 映前5天 | C29: GitHub Actions | D29: 565.1 | E29: 猫眼专业版
A30: 2026-08-06 23:01 | B30: 映前5天 | C30: 定时任务 | D30: 565.5 | E30: 猫眼专业版

Sheet 预售增长分析
A1: 《欢迎来龙餐馆》预售票房增长分析（2026-08-06 映前5天）
A2: 序号 | B2: 获取时间 | C2: 阶段 | D2: 预售票房(万) | E2: 较前次增量(万) | F2: 较22:02增量(万) | G2: 增幅(%) | H2: 数据来源
A3: 1 | B3: 2026-08-06 21:52:32 | C3: 映前5天 | D3: 497.8 | E3: — | F3: -4.9 | G3: +-1.0% | H3: GitHub Actions
A4: 2 | B4: 2026-08-06 22:02:00 | C4: 映前5天 | D4: 502.7 | E4: +4.9 | F4: —（基准） | G4: — | H4: 定时任务
A5: 3 | B5: 2026-08-06 22:30:00 | C5: 映前5天 | D5: 525.7 | E5: +23.0 | F5: +23.0 | G5: +4.6% | H5: GitHub Actions
A6: 4 | B6: 2026-08-06 22:50:40 | C6: 映前5天 | D6: 555.3 | E6: +29.6 | F6: +52.6 | G6: +10.5% | H6: 定时任务
A7: 5 | B7: 2026-08-06 23:00:29 | C7: 映前5天 | D7: 565.1 | E7: +9.8 | F7: +62.4 | G7: +12.4% | H7: GitHub Actions
A8: 6 | B8: 2026-08-06 23:01:02 | C8: 映前5天 | D8: 565.5 | E8: +0.4 | F8: +62.8 | G8: +12.5% | H8: 定时任务
A10: 增长分析汇总
A11: 起始时间 | B11: 2026-08-06 22:02:00 | C11: 基准票房 | D11: 502.7万
A12: 最新时间 | B12: 2026-08-06 23:01:02 | C12: 最新票房 | D12: 565.5万
A13: 总增长(较22:02) | B13: +62.8万 | C13: 增幅 | D13: +12.5% | E13: 时长 | F13: 约59分钟 | G13: 平均增速 | H13: 63.9万/小时
A14: 总增长(较21:52) | B14: +67.7万 | C14: 增幅 | D14: +13.6% | E14: 时长 | F14: 约69分钟 | G14: 平均增速 | H14: 58.9万/小时
A16: 分时段增速明细
A17: 时段 | B17: 时长 | C17: 起始票房(万) | D17: 结束票房(万) | E17: 增量(万) | F17: 增速(万/小时) | G17: 增速评价
A18: 21:52 → 22:02 | B18: 10分钟 | C18: 497.8 | D18: 502.7 | E18: +4.9 | F18: 29.4 | G18: 中等增长
A19: 22:02 → 22:30 | B19: 28分钟 | C19: 502.7 | D19: 525.7 | E19: +23.0 | F19: 49.3 | G19: 稳定增长
A20: 22:30 → 22:50 | B20: 20分钟 | C20: 525.7 | D20: 555.3 | E20: +29.6 | F20: 88.8 | G20: 高速增长
A21: 22:50 → 23:01 | B21: 11分钟 | C21: 555.3 | D21: 565.5 | E21: +10.2 | F21: 55.6 | G21: 稳定增长

Sheet 抓娃娃基准对比
A1: 抓娃娃 vs 来龙餐馆 预售基准对比分析
A3: 一、抓娃娃每日新增点映及预售总票房（基准）
A4: 阶段 | B4: 每日新增(万) | C4: 日增长率 | D4: 累计(万) | E4: 增长倍数(vs前日) | F4: 备注
A5: 映前5天 | B5: 579.5 | C5: — | D5: 579.5 | E5: — | F5: 预售首日
A6: 映前4天 | B6: 1630.24 | C6: +181% | D6: 2209.74 | E6: 2.81x | F6: 稳步增长
A7: 映前3天 | B7: 14876.95 | C7: +813% | D7: 17086.69 | E7: 9.13x | F7: 点映开始!! 爆发
A8: 映前2天 | B8: 19202.61 | C8: +29% | D8: 36289.3 | E8: 1.29x | F8: 点映高峰
A9: 映前1天 | B9: 14188.64 | C9: +-26% | D9: 50477.94 | E9: 0.74x | F9: 首映前夕
A11: 关键比率: 映前5天→4天增长 2.81x | 日均增速(映前4天) 67.9万/h
A13: 二、来龙餐馆当前进度（8/7 映前4天）
A14: 指标 | B14: 数值 | C14: 说明
A15: 8/6收尾累计(映前5天) | B15: 565.5万 | C15: 8/6 23:01实测值
A16: 当前累计(8/7 01:29) | B16: 618.1万 | C16: 最新获取数据
A17: 8/7已新增 | B17: 52.6万 | C17: 约1.5小时增长，增速35.1万/h
A18: 8/7目标新增 | B18: 1630.24万 | C18: 对标抓娃娃映前4天
A19: 8/7目标累计 | B19: 2195.74万 | C19: =565.5 + 1630.24
A20: 剩余需增长 | B20: 1577.64万 | C20: 目标1630.24 - 已完成52.6
A21: 剩余时间 | B21: 21.5小时 | C21: 至8/7 23:00
A22: 所需平均增速 | B22: 73.4万/h | C22: V3预测仅43.3万/h，需达成的1.7倍
A23: V3预测8/7累计 | B23: 1181.9万 | C23: 比目标低1013.8万
A24: V3预测8/7新增 | B24: 616.4万 | C24: 比目标低1013.8万
A26: 三、达成1630.24万目标的逐小时所需增速
A27: 时段 | B27: 时长(h) | C27: 时段系数 | D27: 所需增速(万/h) | E27: 时段新增(万) | F27: 累计(万) | G27: 难度评估
A28: 01:30-06:00 凌晨 | B28: 4.5 | C28: 0.15 | D28: 16.3 | E28: 73.6 | F28: 691.7 | G28: 轻松
A29: 06:00-10:00 早晨 | B29: 4 | C29: 0.3 | D29: 32.7 | E29: 130.8 | F29: 822.5 | G29: 可行
A30: 10:00-12:00 上午 | B30: 2 | C30: 0.55 | D30: 59.9 | E30: 119.9 | F30: 942.4 | G30: 有挑战
A31: 12:00-14:00 午间 | B31: 2 | C31: 0.7 | D31: 76.3 | E31: 152.6 | F31: 1095 | G31: 困难
A32: 14:00-18:00 下午 | B32: 4 | C32: 0.9 | D32: 98.1 | E32: 392.4 | F32: 1487.4 | G32: 困难
A33: 18:00-23:00 晚间 | B33: 5 | C33: 1.3 | D33: 141.7 | E33: 708.4 | F33: 2195.8 | G33: 极难
A35: 四、对比分析与结论
A36: • 抓娃娃映前5天→4天增长比 2.81x（579.5万→1630.24万，日增1050.74万）
A37: • 龙餐馆映前5天收尾 565.5万，按同比例等效目标 1590.86万，设定目标 1630.24万
A38: • 达成目标需8/7全天平均增速 73.4万/h，是V3预测(43.3万/h)的 1.7倍
A39: • 关键时段：18:00-23:00晚间需贡献约708万，占比约45%
A40: • V3预测8/7累计仅1181.9万，比目标低1014万，需大幅修正预期或依赖晚间爆发
A41: • 当前深夜增速偏低(01:29仅35.1万/h)，凌晨时段对总量贡献有限
A42: • 可行性判断：达成目标难度极大，需8/7白天增速显著高于8/6，且晚间出现爆发式增长
A43: • 参考抓娃娃映前3天爆发(14876.95万)，点映开始后增速可能数倍增长，但龙餐馆想看基数远低于抓娃娃
A44: • 建议持续跟踪8/7白天增速趋势，若12:00前累计未达800万，目标基本无法达成

Sheet 预售增长预测
A1: 《欢迎来龙餐馆》预售票房增长预测（V3 修正版）
A2: 基准: 23:01实测 = 565.5万 | 基于14组实测数据修正 | 数据来源: 猫眼专业版 | 更新: 2026-08-06 23:01
A4: 一、实测增速回算（14组数据，14:45-23:01）
A5: 时间段 | B5: 时长(min) | C5: 增长(万) | D5: 小时增速(万/h) | E5: 时段归类 | F5: 备注
A6: 14:45-14:55 | B6: 10 | C6: 11.5 | D6: 69 | E6: 开售首波 | F6: 爆发期，预售刚开放
A7: 14:55-15:01 | B7: 6 | C7: 8.4 | D7: 84 | E7: 下午高峰 | F7: 开售高峰延续
A8: 15:01-15:03 | B8: 2 | C8: 3.5 | D8: 105 | E8: 短暂冲高 | F8: 极短时脉冲
A9: 15:03-16:53 | B9: 110 | C9: 103.9 | D9: 56.7 | E9: 下午平稳 | F9: 通勤时段稳定增长
A10: 16:53-17:37 | B10: 44 | C10: 26.6 | D10: 36.3 | E10: 傍晚过渡 | F10: 晚饭前回落
A11: 17:37-18:03 | B11: 26 | C11: 18.9 | D11: 43.6 | E11: 晚高峰前 | F11: 逐步回升
A12: 18:03-20:02 | B12: 119 | C12: 81.1 | D12: 40.9 | E12: 晚间平稳 | F12: 持续稳定增长
A13: 20:02-21:52 | B13: 110 | C13: 63.6 | D13: 34.7 | E13: 晚间回落 | F13: 增速逐步下降
A14: 21:52-22:02 | B14: 10 | C14: 4.9 | D14: 29.4 | E14: 深夜前低谷 | F14: 晚间最低速
A15: 22:02-22:30 | B15: 28 | C15: 23 | D15: 49.3 | E15: 夜间回升 | F15: 22点后小幅反弹
A16: 22:30-22:50 | B16: 20 | C16: 29.6 | D16: 88.8 | E16: 夜间脉冲 | F16: 疑似集中下单(异常高)
A17: 22:50-23:01 | B17: 11 | C17: 10.2 | D17: 55.6 | E17: 深夜收尾 | F17: 脉冲后回落
A18: 排除首波+脉冲后均值 | B18: 8组稳态均值 | D18: 43.3 | E18: 晚间均值42.0万/h | 白天均值45.5万/h
A20: 二、V3模型参数（基于14组实测数据修正）
A21: 参数 | B21: V2旧值 | C21: V3修正值 | D21: 修正依据
A22: 基准增速(万/h) | B22: 58.2 | C22: 43.3 | D22: 8组稳态实测均值(排除首波3组+脉冲1组)，较V2大幅下调
A23: 晚间系数(18-23时) | B23: 1 | C23: 0.97 | D23: 晚间均值42.0/基准43.3，晚间略低于白天
A24: 深夜系数(23-01时) | B24: 0.7 | C24: 0.55 | D24: 23点后增速明显回落，参照21:52-22:02的29.4万/h
A25: 凌晨系数(01-06时) | B25: 0.12 | C25: 0.1 | D25: 深夜购票几乎停滞
A26: 早晨系数(06-10时) | B26: 0.3 | C26: 0.25 | D26: 少量恢复
A27: 上午系数(10-12时) | B27: 0.5 | C27: 0.45 | D27: 平稳低速
A28: 午间系数(12-14时) | B28: 0.65 | C28: 0.55 | D28: 午间小幅回升
A29: 下午系数(14-18时) | B29: 0.75 | C29: 0.75 | D29: 下午增速回升，保持不变
A30: 映前5天日期系数(8/6) | B30: 0.8 | C30: 1 | D30: 作为基准日=1.0，其他日期相对调整
A31: 映前4天日期系数(8/7) | B31: 1.2 | C31: 1.15 | D31: 宣发发酵，但想看基数低(2.5万)，适度上调
A32: 映前3天日期系数(8/8) | B32: 1.5 | C32: 1.35 | D32: 点映前半天，预期温和增长
A33: 点映系数(8/8 14:00+) | B33: 3 | C33: 2.5 | D33: 点映票房计入，但想看基数偏低
A35: 三、逐小时预测（8月6日23:00 - 8月8日14:00点映开始）
A36: 时间 | B36: 星期 | C36: 预测增速(万/h) | D36: 预测累计(万) | E36: 时段说明 | F36: 置信度
A37: 08-06 23:00 | B37: 周四 | C37: —（实际值） | D37: 565.5 | E37: 映前5天·实测基准 | F37: 实际
A38: 08-07 00:00 | B38: 周五 | C38: 23.8 | D38: 589.3 | E38: 映前4天·深夜回落 | F38: 中
A39: 08-07 01:00 | B39: 周五 | C39: 27.4 | D39: 616.7 | E39: 映前4天·凌晨低谷 | F39: 中
A40: 08-07 02:00 | B40: 周五 | C40: 5 | D40: 621.7 | E40: 映前4天·凌晨低谷 | F40: 中
A41: 08-07 03:00 | B41: 周五 | C41: 5 | D41: 626.7 | E41: 映前4天·凌晨低谷 | F41: 中
A42: 08-07 04:00 | B42: 周五 | C42: 5 | D42: 631.6 | E42: 映前4天·凌晨低谷 | F42: 中
A43: 08-07 05:00 | B43: 周五 | C43: 5 | D43: 636.6 | E43: 映前4天·凌晨低谷 | F43: 中
...

Sheet 想看数据明细
A1: 映前想看数据逐日明细
A2: 映前天数 | B2: 抓娃娃 | C2: 独行月球 | D2: 欢迎来龙餐馆
A3: 映前1天 | B3: 17972 | C3: 46323
A4: 映前2天 | B4: 24361 | C4: 37332
A5: 映前3天 | B5: 24128 | C5: 23360
A6: 映前4天 | B6: 15018 | C6: 22233
A7: 映前5天 | B7: 12511 | C7: 19513
A8: 映前6天 | B8: 14210 | C8: 18698 | D8: 24881
A9: 映前7天 | B9: 16021 | C9: 22717
A10: 映前8天 | B10: 12887 | C10: 18102
A11: 映前9天 | C11: 36276
A12: 映前10天 | C12: 60466
A13: 抓娃娃合计 | B13: =SUM(B3:B10)
A14: 抓娃娃日均 | B14: =AVERAGE(B3:B10)
A15: 抓娃娃峰值 | B15: =MAX(B3:B10)
A16: 独行月球合计 | C16: =SUM(C3:C12)
A17: 独行月球日均 | C17: =AVERAGE(C3:C12)
A18: 独行月球峰值 | C18: =MAX(C3:C12)
A19: 来龙餐馆合计 | D19: =SUM(D3:D8)
A20: 来龙餐馆日均(有效) | D20: =D8
A21: 来龙餐馆峰值 | D21: =MAX(D3:D8)
A23: 注：欢迎来龙餐馆映前1-5天暂无想看数据，仅映前6天有值(24881)；该片8月11日上映，数据持续更新中。

Sheet 预售与票房节点
A1: 预售与票房关键节点数据
A2: 电影 | B2: 数据类型 | C2: 时间节点 | D2: 金额(元) | E2: 说明
A3: 抓娃娃 | B3: 预售 | C3: 映前10天(07-06) | D3: 630000 | E3: 当日新增63.0万
A4: 抓娃娃 | B4: 预售 | C4: 映前4天(07-12) | D4: 1720000 | E4: 当日新增17.2万
A5: 抓娃娃 | B5: 预售 | C5: 映前3天(07-13) | D5: 3450000 | E5: 当日新增34.5万，点映首日
A6: 抓娃娃 | B6: 预售 | C6: 映前2天(07-14) | D6: 15640000 | E6: 当日新增156.4万
A7: 抓娃娃 | B7: 预售 | C7: 映前1天(07-15) | D7: 138260000 | E7: 当日新增1382.6万，预售集中爆发
A8: 抓娃娃 | B8: 票房 | C8: 2024-07-13(点映首日) | D8: 156000000 | E8: 点映首日单日票房约1.56亿
A9: 抓娃娃 | B9: 票房 | C9: 2024-07-16(上映首日) | D9: 650000000 | E9: 正式上映首日票房6.5亿
A10: 抓娃娃 | B10: 票房 | C10: 2024-07-20(上映第4天) | D10: 1100000000 | E10: 票房突破11亿
A11: 抓娃娃 | B11: 票房 | C11: 累计总票房 | D11: 3300000000 | E11: 累计票房超33亿，暑期档冠军
A12: 独行月球 | B12: 预售 | C12: 映前10天(07-19) | D12: 890000 | E12: 当日新增8.9万
A13: 独行月球 | B13: 预售 | C13: 映前7天(07-22) | D13: 2582000 | E13: 当日新增258.2万
A14: 独行月球 | B14: 预售 | C14: 映前4天(07-25) | D14: 27200000 | E14: 当日新增272.0万
... A21: 欢迎来龙餐馆 | B21: 预售 | C21: 2026-08-06 14:45(映前5天) | D21: 18030000 | E21: 点映及预售总票房180.3万；预售总票房3.5万；首日预售3.0万；首日排片占比77.1%；首日黄金场占比78.6%
A22: 欢迎来龙餐馆 | B22: 票房 | C22: 未上映 | D22: — | E22: 8月11日全国公映，8月8-10日超前点映
A23: 数据来源：猫眼专业版；金额为关键节点公开数据。
